<?xml version="1.0" encoding="utf-8"?>
<!-- =================================================================================== -->
<!-- |    This document was autogenerated by xacro from robot_1.urdf.xacro             | -->
<!-- |    EDITING THIS FILE BY HAND IS NOT RECOMMENDED                                 | -->
<!-- =================================================================================== -->
<robot name="robot_1">

<!--   <link name="base_footprint"/>

  <joint name="base_joint" type="fixed">
    <origin rpy="0 0 0" xyz="0 0 0.1"/>
    <parent link="base_footprint"/>
    <child link="base_link"/>
  </joint> -->

  <link name="base_link">
    <visual>
      <origin rpy="0 0 0" xyz="0 0 0.01"/>
      <geometry>
        <box size="0.5 0.25 0.1"/>
      </geometry>
    </visual>
    <collision>
      <origin rpy="0 0 0" xyz="0 0 0"/>
      <geometry>
        <box size="0.5 0.25 0.1"/>
      </geometry>
    </collision>
    <inertial>
      <mass value="1"/>
      <origin xyz="0 0 0"/>
      <inertia ixx="0.00604166666667" ixy="0" ixz="0" iyy="0.0216666666667" iyz="0" izz="0.0260416666667"/>
    </inertial>
  </link>

  <gazebo reference="base_link">
    <material>Gazebo/Black</material>
  </gazebo>
  <!-- <xacro:wheel prefix="right">
    <origin xyz="0 -${base_width/2+wheel_thickness/2} 0" rpy="0 0 0" />
  </xacro:wheel>
  <xacro:wheel prefix="left">
    <origin xyz="0 ${base_width/2+wheel_thickness/2} 0" rpy="0 0 0" />
  </xacro:wheel> -->
  <link name="front_right_wheel">
    <inertial>
      <origin rpy="1.570795 0 0" xyz="0 0 0"/>
      <mass value="1"/>
      <inertia ixx="0.00270833333333" ixy="0" ixz="0" iyy="0.00270833333333" iyz="0" izz="0.005"/>
    </inertial>
    <visual>
      <origin rpy="1.570795 0 0" xyz="0 0 0"/>
      <geometry>
        <cylinder length="0.05" radius="0.1"/>
      </geometry>
    </visual>
    <collision>
      <origin rpy="1.570795 0 0" xyz="0 0 0"/>
      <geometry>
        <cylinder length="0.05" radius="0.1"/>
      </geometry>
    </collision>
  </link>
  <gazebo reference="front_right_wheel">
    <mu1 value="1.0"/>
    <mu2 value="1.0"/>
    <kp value="100000.0"/>
    <kd value="1.0"/>
    <!-- <fdir1 value="0 0 0"/> -->
    <slip1>0.5</slip1>
    <slip2>0</slip2>
  </gazebo>
  <joint name="front_right_wheel_joint" type="continuous">
    <parent link="base_link"/>
    <child link="front_right_wheel"/>
    <origin rpy="0 0 0" xyz="0.125 -0.15 0"/>
    <axis rpy="0 0 0" xyz="0 1 0"/>
  </joint>
<!--   <transmission name="front_right_wheel_trans" type="SimpleTransmission">
    <type>transmission_interface/SimpleTransmission</type>
    <actuator name="front_right_wheel_motor">
      <mechanicalReduction>1</mechanicalReduction>
    </actuator>
    <joint name="front_right_wheel_joint">
      <hardwareInterface>hardware_interface/VelocityJointInterface</hardwareInterface>
    </joint>
  </transmission> -->
  <gazebo reference="front_right_wheel">
    <material>Gazebo/Red</material>
  </gazebo>

  <link name="front_left_wheel">
    <inertial>
      <origin rpy="1.570795 0 0" xyz="0 0 0"/>
      <mass value="1"/>
      <inertia ixx="0.00270833333333" ixy="0" ixz="0" iyy="0.00270833333333" iyz="0" izz="0.005"/>
    </inertial>
    <visual>
      <origin rpy="1.570795 0 0" xyz="0 0 0"/>
      <geometry>
        <cylinder length="0.05" radius="0.1"/>
      </geometry>
    </visual>
    <collision>
      <origin rpy="1.570795 0 0" xyz="0 0 0"/>
      <geometry>
        <cylinder length="0.05" radius="0.1"/>
      </geometry>
    </collision>
  </link>

  <gazebo reference="front_left_wheel">
    <mu1 value="1.0"/>
    <mu2 value="1.0"/>
    <kp value="100000.0"/>
    <kd value="1.0"/>
    <!-- <fdir1 value="0 0 0"/> -->
    <slip1>0.5</slip1>
    <slip2>0</slip2>
  </gazebo>
  <joint name="front_left_wheel_joint" type="continuous">
    <parent link="base_link"/>
    <child link="front_left_wheel"/>
    <origin rpy="0 0 0" xyz="0.125 0.15 0"/>
    <axis rpy="0 0 0" xyz="0 1 0"/>
  </joint>
<!--   <transmission name="front_left_wheel_trans" type="SimpleTransmission">
    <type>transmission_interface/SimpleTransmission</type>
    <actuator name="front_left_wheel_motor">
      <mechanicalReduction>1</mechanicalReduction>
    </actuator>
    <joint name="front_left_wheel_joint">
      <hardwareInterface>hardware_interface/VelocityJointInterface</hardwareInterface>
    </joint>
  </transmission> -->
  <gazebo reference="front_left_wheel">
    <material>Gazebo/Red</material>
  </gazebo>

  <link name="back_right_wheel">
    <inertial>
      <origin rpy="1.570795 0 0" xyz="0 0 0"/>
      <mass value="1"/>
      <inertia ixx="0.00270833333333" ixy="0" ixz="0" iyy="0.00270833333333" iyz="0" izz="0.005"/>
    </inertial>
    <visual>
      <origin rpy="1.570795 0 0" xyz="0 0 0"/>
      <geometry>
        <cylinder length="0.05" radius="0.1"/>
      </geometry>
    </visual>
    <collision>
      <origin rpy="1.570795 0 0" xyz="0 0 0"/>
      <geometry>
        <cylinder length="0.05" radius="0.1"/>
      </geometry>
    </collision>
  </link>

  <gazebo reference="back_right_wheel">
    <mu1 value="1.0"/>
    <mu2 value="1.0"/>
    <kp value="100000.0"/>
    <kd value="1.0"/>
    <!-- <fdir1 value="0 0 0"/> -->
    <slip1>0.5</slip1>
    <slip2>0</slip2>
  </gazebo>
  <joint name="back_right_wheel_joint" type="continuous">
    <parent link="base_link"/>
    <child link="back_right_wheel"/>
    <origin rpy="0 0 0" xyz="-0.125 -0.15 0"/>
    <axis rpy="0 0 0" xyz="0 1 0"/>
  </joint>
<!--   <transmission name="back_right_wheel_trans" type="SimpleTransmission">
    <type>transmission_interface/SimpleTransmission</type>
    <actuator name="back_right_wheel_motor">
      <mechanicalReduction>1</mechanicalReduction>
    </actuator>
    <joint name="back_right_wheel_joint">
      <hardwareInterface>hardware_interface/VelocityJointInterface</hardwareInterface>
    </joint>
  </transmission> -->
  <gazebo reference="back_right_wheel">
    <material>Gazebo/Red</material>
  </gazebo>
  <link name="back_left_wheel">
    <inertial>
      <origin rpy="1.570795 0 0" xyz="0 0 0"/>
      <mass value="1"/>
      <inertia ixx="0.00270833333333" ixy="0" ixz="0" iyy="0.00270833333333" iyz="0" izz="0.005"/>
    </inertial>
    <visual>
      <origin rpy="1.570795 0 0" xyz="0 0 0"/>
      <geometry>
        <cylinder length="0.05" radius="0.1"/>
      </geometry>
    </visual>
    <collision>
      <origin rpy="1.570795 0 0" xyz="0 0 0"/>
      <geometry>
        <cylinder length="0.05" radius="0.1"/>
      </geometry>
    </collision>
  </link>
  <gazebo reference="back_left_wheel">
    <mu1 value="1.0"/>
    <mu2 value="1.0"/>
    <kp value="10000.0"/>
    <kd value="1.0"/>
    <!-- <fdir1 value="0 0 0"/> -->
    <slip1>0.5</slip1>
    <slip2>0</slip2>
  </gazebo>
  <joint name="back_left_wheel_joint" type="continuous">
    <parent link="base_link"/>
    <child link="back_left_wheel"/>
    <origin rpy="0 0 0" xyz="-0.125 0.15 0"/>
    <axis rpy="0 0 0" xyz="0 1 0"/>
  </joint>
  <!-- <transmission name="back_left_wheel_trans" type="SimpleTransmission">
    <type>transmission_interface/SimpleTransmission</type>
    <actuator name="back_left_wheel_motor">
      <mechanicalReduction>1</mechanicalReduction>
    </actuator>
    <joint name="back_left_wheel_joint">
      <hardwareInterface>hardware_interface/VelocityJointInterface</hardwareInterface>
    </joint>
  </transmission> -->
  <gazebo reference="back_left_wheel">
    <material>Gazebo/Red</material>
  </gazebo>
  <!-- <gazebo>
    <plugin name="gazebo_ros_control" filename="libgazebo_ros_control.so">
      <robotNamespace>/</robotNamespace>
    </plugin>
  </gazebo> -->
  <!-- <gazebo>
    <plugin filename="libgazebo_ros_diff_drive.so" name="differential_drive_controller">
      <alwaysOn>true</alwaysOn>
      <updateRate>20</updateRate>
      <leftJoint>left_wheel_joint</leftJoint>
      <rightJoint>right_wheel_joint</rightJoint>
      <wheelSeparation>${base_width+wheel_thickness}</wheelSeparation>
      <wheelDiameter>${wheel_radius*2}</wheelDiameter>
      <wheelTorque>20</wheelTorque>
      <wheelAcceleration>1.0</wheelAcceleration>
      <commandTopic>cmd_vel</commandTopic>
      <odometryTopic>odom</odometryTopic>
      <odometryFrame>odom</odometryFrame>
      <robotBaseFrame>base_link</robotBaseFrame>
    </plugin>
  </gazebo> -->
  <!-- <gazebo>
    <plugin name="skid_steer_drive_controller" filename="libgazebo_ros_skid_steer_drive.so">
      <updateRate>10.0</updateRate>
      <robotNamespace>/</robotNamespace>
      <leftFrontJoint>front_left_wheel_joint</leftFrontJoint>
      <rightFrontJoint>front_right_wheel_joint</rightFrontJoint>
      <leftRearJoint>back_left_wheel_joint</leftRearJoint>
      <rightRearJoint>back_right_wheel_joint</rightRearJoint>
      <wheelSeparation>${base_width+wheel_thickness}</wheelSeparation>
      <wheelDiameter>${wheel_radius*2}</wheelDiameter>
      <robotBaseFrame>base_footprint</robotBaseFrame>
      <torque>20</torque>
      <MaxForce>5.0</MaxForce>
      <commandTopic>cmd_vel</commandTopic>
      <odometryTopic>odom</odometryTopic>
      <odometryFrame>odom</odometryFrame>
      <broadcastTF>true</broadcastTF>
    </plugin>
  </gazebo> -->
<!--   <gazebo>
    <plugin filename="libgazebo_ros_planar_move.so" name="object_controller">
      <commandTopic>cmd_vel</commandTopic>
      <odometryTopic>odom</odometryTopic>
      <odometryFrame>odom</odometryFrame>
      <odometryRate>20.0</odometryRate>
      <robotNamespace>/</robotNamespace>
      <enableYAxis>false</enableYAxis>
      <leftFrontJoint>front_left_wheel_joint</leftFrontJoint>
      <rightFrontJoint>front_right_wheel_joint</rightFrontJoint>
      <leftRearJoint>back_left_wheel_joint</leftRearJoint>
      <rightRearJoint>back_right_wheel_joint</rightRearJoint>
      <wheelSeparation>0.3</wheelSeparation>
      <wheelDiameter>0.2</wheelDiameter>
      <robotBaseFrame>base_footprint</robotBaseFrame>
    </plugin>
  </gazebo> -->

  <gazebo>
  <plugin name="skid_steer_drive_controller" filename="libgazebo_ros_skid_steer_drive.so">
    <updateRate>100.0</updateRate>
    <robotNamespace>/</robotNamespace>
    <leftFrontJoint>front_left_wheel_joint</leftFrontJoint>
    <rightFrontJoint>front_right_wheel_joint</rightFrontJoint>
    <leftRearJoint>back_left_wheel_joint</leftRearJoint>
    <rightRearJoint>back_right_wheel_joint</rightRearJoint>
    <wheelSeparation>0.3</wheelSeparation>
    <wheelDiameter>0.2</wheelDiameter>
    <robotBaseFrame>base_link</robotBaseFrame>
    <torque>500</torque>
    <topicName>cmd_vel</topicName>
    <broadcastTF>true</broadcastTF>
  </plugin>
</gazebo>
</robot>

